<?xml version="1.0"?>
<robot xmlns:xacro="http://www.ros.org/wiki/xacro" name="ballsbot">
  <material name="blue">
    <color rgba="0 0 0.8 1"/>
  </material>

  <material name="white">
    <color rgba="1 1 1 1"/>
  </material>

  <link name="base_link">
    <visual>
      <geometry>
        <box size="0.38 0.30 0.17"/>
      </geometry>
      <origin xyz="0 0 0.085"/>
      <material name="white"/>
    </visual>
    <collision>
      <geometry>
        <box size="0.38 0.30 0.17"/>
      </geometry>
      <origin xyz="0 0 0.085"/>
    </collision>
  </link>

  <link name="lidar">
    <visual>
      <geometry>
        <cylinder length="0.03" radius="0.03"/>
      </geometry>
      <material name="blue"/>
    </visual>
  </link>

  <joint name="body_to_lidar" type="fixed">
    <parent link="base_link"/>
    <child link="lidar"/>
    <origin xyz="-0.108 0.0 0.250"/>
  </joint>

  <link name="m0" />

  <joint name="m0-joint" type="revolute">
    <parent link="base_link"/>
    <child link="m0"/>
    <origin xyz="0.087 0.0 0.145"/>
    <axis xyz="0 0 1"/>
    <limit effort="1000.0" lower="1.0554" upper="-1.0554" velocity="0.5"/>
  </joint>

  <link name="m1" />

  <joint name="m1-joint" type="revolute">
    <parent link="m0"/>
    <child link="m1"/>
    <origin xyz="0.035 0.0 0.045" />
    <axis xyz="0 1 0"/>
    <limit effort="1000.0" lower="-1.57" upper="1.4972" velocity="0.5"/>
  </joint>

  <link name="m2" />

  <joint name="m2-joint" type="revolute">
    <parent link="m1"/>
    <child link="m2"/>
    <origin xyz="0.005 0.0 0.165" />
    <axis xyz="0 1 0"/>
    <limit effort="1000.0" lower="-0.859" upper="1.57" velocity="0.5"/>
  </joint>

  <xacro:macro name="claw" params="prefix reflect">
    <link name="m-claw-${prefix}" />

    <joint name="m-claw-${prefix}-joint" type="revolute">
      <parent link="m2"/>
      <child link="m-claw-${prefix}"/>
      <origin xyz="0.240 ${reflect*(0.02)} -0.005" />
      <axis xyz="0 0 1"/>
      <limit effort="1000.0" lower="0.0" upper="${reflect*(1.1781)" velocity="0.5"/>
    </joint>
  </xacro:macro>
  <xacro:claw prefix="left" reflect="1" />
  <xacro:claw prefix="right" reflect="-1" />
</robot>